<?xml version="1.0" ?>
<robot xmlns:xacro="http://ros.org/wiki/xacro">

  <!-- Import all Gazebo-customization elements, including Gazebo colors -->
  <xacro:include filename="$(find bound_mpc)/urdf/body/iiwa.gazebo.xacro" />
  <!-- Include Utilities -->
  <xacro:include filename="$(find bound_mpc)/urdf/body/utilities.xacro" />

  <!-- some constants -->
  <xacro:property name="safety_controller_k_pos" value="100" />
  <xacro:property name="safety_controller_k_vel" value="2" /> 
  <xacro:property name="joint_damping" value="0.5" />
  <xacro:property name="max_effort" value="320"/>
  <xacro:property name="max_velocity" value="10"/>

  <xacro:macro name="iiwa14" params="parent robot_name *origin">

    <!--joint between {parent} and link_0-->
    <joint name="${parent}_${robot_name}_joint" type="fixed">
      <insert_block name="origin"/>
      <parent link="${parent}"/>
      <child link="${robot_name}_link_0"/>
    </joint>

    <gazebo reference="${parent}_${robot_name}_joint">
      <disableFixedJointLumping>true</disableFixedJointLumping>
    </gazebo>

    <link name="${robot_name}_link_0">
      <inertial>
        <origin xyz="0 -0.01439 0.102503" rpy="0 0 0"/>
        <mass value="6.495"/>
        <inertia ixx="0.0690761441316632"  ixy="0"  ixz="0" iyy="0.0711085586914514" iyz="0" izz="0.0200625854402119"/>
      </inertial>

      <visual>
        <origin xyz="0 0 0" rpy="0 0 0"/>
        <geometry>
          <mesh filename="package://bound_mpc/urdf/body/meshes/iiwa14/visual/base_link.dae"/>
        </geometry>
        <!--material name="Grey"/-->
      </visual>

      <collision>
        <origin xyz="0 0 0" rpy="0 0 0"/>
        <geometry>
          <mesh filename="package://bound_mpc/urdf/body/meshes/iiwa14/collision/link_0.dae"/>
        </geometry>
        <material name="Grey"/>
      </collision>

      <self_collision_checking>
        <origin xyz="0 0 0" rpy="0 0 0"/>
        <geometry>
          <capsule radius="0.15" length="0.25"/>
        </geometry>
      </self_collision_checking>

    </link>

    <!-- joint between link_0 and link_1 -->
    <joint name="${robot_name}_joint_1" type="revolute">
      <parent link="${robot_name}_link_0"/>
      <child link="${robot_name}_link_1"/>
      <origin xyz="0 0 0.1525" rpy="0 0 0"/>
      <axis xyz="0 0 1"/>
      <limit lower="${-170 * PI / 180}" upper="${170 * PI / 180}"
             effort="${max_effort}" velocity="${max_velocity}" />
         <!--safety_controller soft_lower_limit="${-168 * PI / 180}"
           soft_upper_limit="${168 * PI / 180}"
           k_position="${safety_controller_k_pos}"
           k_velocity="${safety_controller_k_vel}"/>
      <dynamics damping="${joint_damping}"/-->
    </joint>

    <link name="${robot_name}_link_1">
      <inertial>
        <origin xyz="0 -0.01439 0.102503" rpy="0 0 0"/>
        <mass value="6.495"/>
        <inertia ixx="0.0690761441316632"  ixy="0"  ixz="0" iyy="0.0711085586914514" iyz="0" izz="0.0200625854402119"/>
      </inertial>

      <visual>
        <origin xyz="0 0 0" rpy="0 0 0"/>
        <geometry>
          <mesh filename="package://bound_mpc/urdf/body/meshes/iiwa14/visual/link_1.dae"/>
        </geometry>
        <!--material name="Orange"/-->
      </visual>

      <collision>
        <origin xyz="0 0 0" rpy="0 0 0"/>
        <geometry>
          <mesh filename="package://bound_mpc/urdf/body/meshes/iiwa14/collision/link_1.dae"/>
        </geometry>
        <!--material name="Orange"/-->
      </collision>
    </link>

    <!-- joint between link_1 and link_2 -->
    <joint name="${robot_name}_joint_2" type="revolute">
      <parent link="${robot_name}_link_1"/>
      <child link="${robot_name}_link_2"/>
      <origin xyz="0 0 0.2075" rpy="${PI / 2}   0 ${PI}"/>
      <axis xyz="0 0 1"/>
      <limit lower="${-120 * PI / 180}" upper="${120 * PI / 180}"
             effort="${max_effort}" velocity="${max_velocity}" />
       <!--safety_controller soft_lower_limit="${-118 * PI / 180}"
           soft_upper_limit="${118 * PI / 180}"
           k_position="${safety_controller_k_pos}"
           k_velocity="${safety_controller_k_vel}"/>
      <dynamics damping="${joint_damping}"/-->
    </joint>

    <link name="${robot_name}_link_2">
      <inertial>
        <origin xyz="1.2e-05 0.06472 0.004804" rpy="0 0 0"/>
        <mass value="8.807"/>
        <inertia ixx="0.0824701683534692"  ixy="0"  ixz="0" iyy="0.0164110968055191" iyz="0" izz="0.0873510892661361" />
      </inertial>

      <visual>
        <origin xyz="0 0 -0.013" rpy="0 0 ${PI}"/>
        <geometry>
          <mesh filename="package://bound_mpc/urdf/body/meshes/iiwa14/visual/link_2.dae"/>
        </geometry>
        <!--material name="Orange"/-->
      </visual>

      <collision>
        <origin xyz="0 0 -0.013" rpy="0 0 ${PI}"/>
        <geometry>
          <mesh filename="package://bound_mpc/urdf/body/meshes/iiwa14/collision/link_2.dae"/>
        </geometry>
        <material name="Orange"/>
      </collision>
    </link>

    <!-- joint between link_2 and link_3 -->
    <joint name="${robot_name}_joint_3" type="revolute">
      <parent link="${robot_name}_link_2"/>
      <child link="${robot_name}_link_3"/>
      <origin xyz="0 0.2325 0" rpy="${PI / 2} 0 ${PI}"/>
      <axis xyz="0 0 1"/>
      <limit lower="${-170 * PI / 180}" upper="${170 * PI / 180}"
             effort="${max_effort}" velocity="${max_velocity}" />
       <!--safety_controller soft_lower_limit="${-168 * PI / 180}"
           soft_upper_limit="${168 * PI / 180}"
           k_position="${safety_controller_k_pos}"
           k_velocity="${safety_controller_k_vel}"/>
      <dynamics damping="${joint_damping}"/-->
    </joint>

    <link name="${robot_name}_link_3">
      <inertial>
        <origin xyz="-2.08e-04 0.01601 0.087283" rpy="0 0 0"/>
        <mass value="2.8"/>
        <inertia ixx="0.0230152941318817"  ixy="0"  ixz="0" iyy="0.0228661554143474" iyz="0" izz="0.0554482283748983" />
      </inertial>

      <visual>
        <origin xyz="0 0 0" rpy="0 0 0"/>
        <geometry>
          <mesh filename="package://bound_mpc/urdf/body/meshes/iiwa14/visual/link_3.dae"/>
        </geometry>
        <material name="Orange"/>
      </visual>

      <collision>
        <origin xyz="0 0 0" rpy="0 0 0"/>
        <geometry>
          <mesh filename="package://bound_mpc/urdf/body/meshes/iiwa14/collision/link_3.dae"/>
        </geometry>
        <material name="Orange"/>
      </collision>
    </link>

   <!-- joint between link_3 and link_4 -->
    <joint name="${robot_name}_joint_4" type="revolute">
      <parent link="${robot_name}_link_3"/>
      <child link="${robot_name}_link_4"/>
      <origin xyz="0 0 0.1875" rpy="${PI / 2} 0 0"/>
      <axis xyz="0 0 1"/>
      <limit lower="${-120 * PI / 180}" upper="${120 * PI / 180}"
             effort="${max_effort}" velocity="${max_velocity}" />
       <!--safety_controller soft_lower_limit="${-118 * PI / 180}"
           soft_upper_limit="${118 * PI / 180}"
           k_position="${safety_controller_k_pos}"
           k_velocity="${safety_controller_k_vel}"/>
      <dynamics damping="${joint_damping}"/-->
    </joint>

    <link name="${robot_name}_link_4">
      <inertial>
        <origin xyz="-2.03e-04 0.098639 0.011478" rpy="0 0 0"/>
        <mass value="5.283"/>
        <inertia ixx="0.0472789668341968"  ixy="0"  ixz="0" iyy="0.00964726804146909" iyz="0" izz="0.0466529007761679" />
      </inertial>

      <visual>
        <origin xyz="0 0 -0.011" rpy="0 0 0"/>
        <geometry>
          <mesh filename="package://bound_mpc/urdf/body/meshes/iiwa14/visual/link_4.dae"/>
        </geometry>
        <material name="Orange"/>
      </visual>

      <collision>
        <origin xyz="0 0 -0.011" rpy="0 0 0"/>
        <geometry>
          <mesh filename="package://bound_mpc/urdf/body/meshes/iiwa14/collision/link_4.dae"/>
        </geometry>
        <material name="Orange"/>
      </collision>
    </link>

    <!-- joint between link_4 and link_5 -->
    <joint name="${robot_name}_joint_5" type="revolute">
      <parent link="${robot_name}_link_4"/>
      <child link="${robot_name}_link_5"/>
      <origin xyz="0 0.2125 0" rpy="${-PI / 2} ${PI} 0"/>
      <axis xyz="0 0 1"/>
      <limit lower="${-170 * PI / 180}" upper="${170 * PI / 180}"
             effort="${max_effort}" velocity="${max_velocity}" />
       <!--safety_controller soft_lower_limit="${-168 * PI / 180}"
           soft_upper_limit="${168 * PI / 180}"
           k_position="${safety_controller_k_pos}"
           k_velocity="${safety_controller_k_vel}"/>
      <dynamics damping="${joint_damping}"/-->
    </joint>

    <link name="${robot_name}_link_5">
      <inertial>
        <origin xyz="5.7e-05 0.014468 0.062938" rpy="0 0 0"/>
        <mass value="1.889"/>
        <inertia ixx="0.0138359953358589"  ixy="0"  ixz="0" iyy="0.0116859337751969" iyz="0" izz="0.00571863785412578" />
      </inertial>

      <visual>
        <origin xyz="0 0 0" rpy="0 0 ${PI}"/>
        <geometry>
          <mesh filename="package://bound_mpc/urdf/body/meshes/iiwa14/visual/link_5.dae"/>
        </geometry>
        <material name="Orange"/>
      </visual>

      <collision>
        <origin xyz="0 0 0" rpy="0 0 ${PI}"/>
        <geometry>
          <mesh filename="package://bound_mpc/urdf/body/meshes/iiwa14/collision/link_5.dae"/>
        </geometry>
        <material name="Orange"/>
      </collision>
    </link>

 <!-- joint between link_5 and link_6 -->
    <joint name="${robot_name}_joint_6" type="revolute">
      <parent link="${robot_name}_link_5"/>
      <child link="${robot_name}_link_6"/>
      <origin xyz="0 0 0.1875" rpy="${PI / 2} 0 0"/>
      <axis xyz="0 0 1"/>
      <limit lower="${-120 * PI / 180}" upper="${120 * PI / 180}"
             effort="${max_effort}" velocity="${max_velocity}" />
       <!--safety_controller soft_lower_limit="${-118 * PI / 180}"
           soft_upper_limit="${118 * PI / 180}"
           k_position="${safety_controller_k_pos}"
           k_velocity="${safety_controller_k_vel}"/>
      <dynamics damping="${joint_damping}"/-->
    </joint>

    <link name="${robot_name}_link_6">
      <inertial>
        <origin xyz="3.63e-04 0.016982 -0.019731" rpy="0 0 0"/>
        <mass value="2.32"/>
        <inertia ixx="0.00732758787216765"  ixy="0"  ixz="0" iyy="0.00477633755783711" iyz="0" izz="0.00606797638550296" />
      </inertial>

      <visual>
        <origin xyz="0 0 -0.061" rpy="0 0 ${PI}"/>
        <geometry>
          <mesh filename="package://bound_mpc/urdf/body/meshes/iiwa14/visual/link_6.dae"/>
        </geometry>
        <material name="Orange"/>
      </visual>

      <collision>
        <origin xyz="0 0 -0.061" rpy="0 0 ${PI}"/>
        <geometry>
          <mesh filename="package://bound_mpc/urdf/body/meshes/iiwa14/collision/link_6.dae"/>
        </geometry>
        <material name="Orange"/>
      </collision>
    </link>

 <!-- joint between link_6 and link_7 -->
    <joint name="${robot_name}_joint_7" type="revolute">
      <parent link="${robot_name}_link_6"/>
      <child link="${robot_name}_link_7"/>
      <origin xyz="0 0.0796 0" rpy="${- PI / 2} ${PI} 0"/>
      <axis xyz="0 0 1"/>
      <limit lower="${-175 * PI / 180}" upper="${175 * PI / 180}"
             effort="${max_effort}" velocity="${max_velocity}" />
       <!--safety_controller soft_lower_limit="${-173 * PI / 180}"
           soft_upper_limit="${173 * PI / 180}"
           k_position="${safety_controller_k_pos}"
           k_velocity="${safety_controller_k_vel}"/>
      <dynamics damping="${joint_damping}"/-->
    </joint>

    <link name="${robot_name}_link_7">
      <inertial>
        <origin xyz="0.001904 -9.3e-05 0.018862" rpy="0 0 0"/>
          <mass value="0.863"/>
        <inertia ixx="0.000884"  ixy="0"  ixz="0" iyy="0.000888" iyz="0" izz="0.001105" />
      </inertial>

      <visual>
        <origin xyz="0 0 0" rpy="0 0 0"/>
        <geometry>
          <mesh filename="package://bound_mpc/urdf/body/meshes/iiwa14/visual/link_7.dae"/>
        </geometry>
        <material name="Grey"/>
      </visual>

      <collision>
        <origin xyz="0 0 0" rpy="0 0 0"/>
        <geometry>
          <mesh filename="package://bound_mpc/urdf/body/meshes/iiwa14/collision/link_7.dae"/>
        </geometry>
        <material name="Grey"/>
      </collision>
    </link>
    

    <!-- Link: Link7 - Endeffector -->
    <joint name="${robot_name}_joint_ee" type="fixed">
      <parent link="${robot_name}_link_7"/>
      <child link="${robot_name}_link_ee"/>
      <!--<origin xyz="0 0 0.045" rpy="0 -${PI/2} 0"/>-->
      <origin xyz="0 0 0.2174" rpy="0 -${PI/2} 0"/>
    </joint>
    
    <link name="${robot_name}_link_ee">
      <inertial>
        <origin rpy="0 0 -${PI/2}" xyz="-0.1476 0.08 -0.093"/>
        <mass value="0.00001"/>
        <inertia ixx="0.000001" ixy="0" ixz="0" iyy="0.0000001" iyz="0" izz="0.000001"/>
      </inertial>
      <visual>
        <origin rpy="0 0 -${PI/2}" xyz="-0.1476 0.08 -0.093"/>
        <geometry>
          <mesh filename="package://bound_mpc/urdf/Gripper/GripperLowRes.STL"/>
        </geometry>
        <material name="Grey"/>
      </visual>
      <collision>
        <origin rpy="0 0 -${PI/2}" xyz="-0.1476 0.08 -0.093"/>
        <geometry>
          <mesh filename="package://bound_mpc/urdf/Gripper/GripperLowRes.STL"/>
        </geometry>
        <material name="Grey"/>
      </collision>
    </link>
    

    <!--Extensions -->
    <xacro:iiwa_gazebo robot_name="${robot_name}" />

  </xacro:macro>

</robot>
